Workbook

Sheet ИТОГО
B1: Миндорстрой РБ
A2: КУП Гроднооблдорстрой
A3: ДРСУ № 161 г. Щучин | G3: Наряд № _________________ | AA3: Сроки | AE3: план | AG3: факт
F4: на | I4: Июль | Q4: 2025 | S4: г. | AA4: Начало работы | AE4: 1 | AG4: 1
A5: Объект: Содержание | J5: по прямой сдельной системе оплаты труда | AA5: Окончание работы | AE5: 30 | AG5: 30
A6: Прорабство: ПУ-3
A7: Бригада: ПУ-3 | Q7: Шифр записи | V7: Номер документа | AA7: Шифр машины | AE7: Шифр работы
A10: Шифр нормативного источника | B10: Описание работ и условий производства | G10: Ед. изм | I10: Задано | X10: Исполнено | AG10: шифр работы
I11: количество работ | M11: на единицу | T11: на весь объём | X11: количество работ | AA11: норма на выполненный объём, чел/час | AC11: норма времени, чел/час | AE11: сумма зарплаты
M12: норма времени чел/час | P12: расценка | T12: норма времени чел/час | V12: Сумма зарплаты
T14: =I14*M14 -> 0 | V14: =I14*P14 -> 0 | X14: =I14 -> 0 | AA14: =T14 -> 0 | AC14: =M14 -> 0 | AE14: =ROUND(V14,2) -> 0
T15: =I15*M15 -> 0 | V15: =I15*P15 -> 0 | X15: =I15 -> 0 | AA15: =T15 -> 0 | AC15: =M15 -> 0 | AE15: =ROUND(V15,2) -> 0
T16: =I16*M16 -> 0 | V16: =I16*P16 -> 0 | X16: =I16 -> 0 | AA16: =T16 -> 0 | AC16: =M16 -> 0 | AE16: =ROUND(V16,2) -> 0
T17: =I17*M17 -> 0 | V17: =I17*P17 -> 0 | X17: =I17 -> 0 | AA17: =T17 -> 0 | AC17: =M17 -> 0 | AE17: =ROUND(V17,2) -> 0
T18: =I18*M18 -> 0 | V18: =I18*P18 -> 0 | X18: =I18 -> 0 | AA18: =T18 -> 0 | AC18: =M18 -> 0 | AE18: =ROUND(V18,2) -> 0
T19: =I19*M19 -> 0 | V19: =I19*P19 -> 0 | X19: =I19 -> 0 | AA19: =T19 -> 0 | AC19: =M19 -> 0 | AE19: =ROUND(V19,2) -> 0
T20: =I20*M20 -> 0 | V20: =I20*P20 -> 0 | X20: =I20 -> 0 | AA20: =T20 -> 0 | AC20: =M20 -> 0 | AE20: =ROUND(V20,2) -> 0
T21: =I21*M21 -> 0 | V21: =I21*P21 -> 0 | X21: =I21 -> 0 | AA21: =T21 -> 0 | AC21: =M21 -> 0 | AE21: =ROUND(V21,2) -> 0
T22: =I22*M22 -> 0 | V22: =I22*P22 -> 0 | X22: =I22 -> 0 | AA22: =T22 -> 0 | AC22: =M22 -> 0 | AE22: =ROUND(V22,2) -> 0
T23: =I23*M23 -> 0 | V23: =I23*P23 -> 0 | X23: =I23 -> 0 | AA23: =T23 -> 0 | AC23: =M23 -> 0 | AE23: =ROUND(V23,2) -> 0
T24: =I24*M24 -> 0 | V24: =I24*P24 -> 0 | X24: =I24 -> 0 | AA24: =T24 -> 0 | AC24: =M24 -> 0 | AE24: =ROUND(V24,2) -> 0
T25: =I25*M25 -> 0 | V25: =I25*P25 -> 0 | X25: =I25 -> 0 | AA25: =T25 -> 0 | AC25: =M25 -> 0 | AE25: =ROUND(V25,2) -> 0
... T32: =I32*M32 -> 0 | V32: =I32*P32 -> 0 | X32: =I32 -> 0 | AA32: =T32 -> 0 | AC32: =M32 -> 0 | AE32: =ROUND(V32,2) -> 0
AB33: ИТОГО | AE33: =SUM(AE14:AF32) -> 0
B35: Задание выдал прораб (мастер) _______________ | G35: =I4 -> Июль | K35: =Q4 -> 2025 | M35: г. | T35: Задание принял бригадир ________________ | AC35: "____" = | AD35: =Q4 -> 2025 | AE35: г.
D36: Работу принял с оценкой качества _______________________________________________
B37: Прораб (мастер) ___________________ | G37: =I4 -> Июль | K37: =Q4 -> 2025 | M37: г. | T37: Работу сдал бригадир ______________________ | AC37: "____" | AD37: =Q4 -> 2025 | AE37: г.
B38: Нормы, расценки и сумма заработной платы проверил экономист: Яцевич Н. Г. ____________________ ________________________ " _____ " | AF38: =Q4 -> 2025 | AG38: г.
B40: Объёмы проверил: ________________Мархоцкая С. К.
D42: Табель расчёт | J42: =I4 -> Июль | P42: =Q4 -> 2025
A43: Табельный № | B43: Фамилия, И. О. | C43: Разряд | D43: Часы работы | T43: часов | Y43: дней | AB43: Причитается
D44: 1 | E44: 2 | F44: 3 | G44: 4 | H44: 5 | I44: 6 | J44: 7 | K44: 8 | L44: 9 | M44: 10 | N44: 11 | O44: 12 | P44: 13 | Q44: 14 | R44: 15 | S44: х | T44: отработано урочно | W44: в простое | X44: всего | Y44: сдельно | Z44: повремённо | AA44: всего | AB44: заработная плата | AF44: доплаты | AG44: всего к оплате
D45: 16 | E45: 17 | F45: 18 | G45: 19 | H45: 20 | I45: 21 | J45: 22 | K45: 23 | L45: 24 | M45: 25 | N45: 26 | O45: 27 | P45: 28 | Q45: 29 | R45: 30 | S45: 31 | T45: сдельно | U45: повремён | V45: сверурочно | AB45: сдельно | AC45: повременно | AD45: сверурочно | AE45: в простое
A46: 1 | B46: Федюк В. В | C46: 6 | D46: =IF('001'!D46+Рабочие!D37+#REF!+#REF!+SDLG!D36+#REF!+#REF!+#REF!+#REF!+#REF!+#REF!+#REF!+#REF!+#REF!+#REF!+#REF!+#REF!+#REF!+'18'!D46+#REF!+#REF!+#REF!+#REF!,'001'!D46+Рабочие!D37+#REF!+#REF!+SDLG!D36+#REF!+#REF!+#REF!+#REF!+#REF!+#REF!+#REF!+#REF!+#REF!+#REF!+#REF!+#REF!+#REF!+'18'!D46+#REF!+#REF!+#REF!+#REF!," ") -> #REF! | E46: =IF('001'!E46+Рабочие!E37+#REF!+#REF!+SDLG!E36+#REF!+#REF!+#REF!+#REF!+#REF!+#REF!+#REF!+#REF!+#REF!+#REF!+#REF!+#REF!+#REF!+'18'!E46+#REF!+#REF!+#REF!+#REF!,'001'!E46+Рабочие!E37+#REF!+#REF!+SDLG!E36+#REF!+#REF!+#REF!+#REF!+#REF!+#REF!+#REF!+#REF!+#REF!+#REF!+#REF!+#REF!+#REF!+'18'!E46+#REF!+#REF!+#REF!+#REF!," ") -> #REF! | F46: =IF('001'!F46+Рабочие!F37+#REF!+#REF!+SDLG!F36+#REF!+#REF!+#REF!+#REF!+#REF!+#REF!+#REF!+#REF!+#REF!+#REF!+#REF!+#REF!+#REF!+'18'!F46+#REF!+#REF!+#REF!+#REF!,'001'!F46+Рабочие!F37+#REF!+#REF!+SDLG!F36+#REF!+#REF!+#REF!+#REF!+#REF!+#REF!+#REF!+#REF!+#REF!+#REF!+#REF!+#REF!+#REF!+'18'!F46+#REF!+#REF!+#REF!+#REF!," ") -> #REF! | G46: =IF('001'!G46+Рабочие!G37+#REF!+#REF!+SDLG!G36+#REF!+#REF!+#REF!+#REF!+#REF!+#REF!+#REF!+#REF!+#REF!+#REF!+#REF!+#REF!+#REF!+'18'!G46+#REF!+#REF!+#REF!+#REF!,'001'!G46+Рабочие!G37+#REF!+#REF!+SDLG!G36+#REF!+#REF!+#REF!+#REF!+#REF!+#REF!+#REF!+#REF!+#REF!+#REF!+#REF!+#REF!+#REF!+'18'!G46+#REF!+#REF!+#REF!+#REF!," ") -> #REF! | H46: =IF('001'!H46+Рабочие!H37+#REF!+#REF!+SDLG!H36+#REF!+#REF!+#REF!+#REF!+#REF!+#REF!+#REF!+#REF!+#REF!+#REF!+#REF!+#REF!+#REF!+'18'!H46+#REF!+#REF!+#REF!+#REF!,'001'!H46+Рабочие!H37+#REF!+#REF!+SDLG!H36+#REF!+#REF!+#REF!+#REF!+#REF!+#REF!+#REF!+#REF!+#REF!+#REF!+#REF!+#REF!+#REF!+'18'!H46+#REF!+#REF!+#REF!+#REF!," ") -> #REF! | I46: =IF('001'!I46+Рабочие!I37+#REF!+#REF!+SDLG!I36+#REF!+#REF!+#REF!+#REF!+#REF!+#REF!+#REF!+#REF!+#REF!+#REF!+#REF!+#REF!+#REF!+'18'!I46+#REF!+#REF!+#REF!+#REF!,'001'!I46+Рабочие!I37+#REF!+#REF!+SDLG!I36+#REF!+#REF!+#REF!+#REF!+#REF!+#REF!+#REF!+#REF!+#REF!+#REF!+#REF!+#REF!+#REF!+'18'!I46+#REF!+#REF!+#REF!+#REF!," ") -> #REF! | J46: =IF('001'!J46+Рабочие!J37+#REF!+#REF!+SDLG!J36+#REF!+#REF!+#REF!+#REF!+#REF!+#REF!+#REF!+#REF!+#REF!+#REF!+#REF!+#REF!+#REF!+'18'!J46+#REF!+#REF!+#REF!+#REF!,'001'!J46+Рабочие!J37+#REF!+#REF!+SDLG!J36+#REF!+#REF!+#REF!+#REF!+#REF!+#REF!+#REF!+#REF!+#REF!+#REF!+#REF!+#REF!+#REF!+'18'!J46+#REF!+#REF!+#REF!+#REF!," ") -> #REF! | K46: =IF('001'!K46+Рабочие!K37+#REF!+#REF!+SDLG!K36+#REF!+#REF!+#REF!+#REF!+#REF!+#REF!+#REF!+#REF!+#REF!+#REF!+#REF!+#REF!+#REF!+'18'!K46+#REF!+#REF!+#REF!+#REF!,'001'!K46+Рабочие!K37+#REF!+#REF!+SDLG!K36+#REF!+#REF!+#REF!+#REF!+#REF!+#REF!+#REF!+#REF!+#REF!+#REF!+#REF!+#REF!+#REF!+'18'!K46+#REF!+#REF!+#REF!+#REF!," ") -> #REF! | ... S46: =IF('001'!S46+Рабочие!S37+#REF!+#REF!+SDLG!S36+#REF!+#REF!+#REF!+#REF!+#REF!+#REF!+#REF!+#REF!+#REF!+#REF!+#REF!+#REF!+#REF!+'18'!S46+#REF!+#REF!+#REF!+#REF!,'001'!S46+Рабочие!S37+#REF!+#REF!+SDLG!S36+#REF!+#REF!+#REF!+#REF!+#REF!+#REF!+#REF!+#REF!+#REF!+#REF!+#REF!+#REF!+#REF!+'18'!S46+#REF!+#REF!+#REF!+#REF!," ") -> #REF! | T46: =SUM(D46:S47) -> #REF! | AG46: =AE94 -> #REF!
D47: =IF('001'!D47+Рабочие!D38+#REF!+#REF!+SDLG!D37+#REF!+#REF!+#REF!+#REF!+#REF!+#REF!+#REF!+#REF!+#REF!+#REF!+#REF!+#REF!+#REF!+'18'!D47+#REF!+#REF!+#REF!+#REF!,'001'!D47+Рабочие!D38+#REF!+#REF!+SDLG!D37+#REF!+#REF!+#REF!+#REF!+#REF!+#REF!+#REF!+#REF!+#REF!+#REF!+#REF!+#REF!+#REF!+'18'!D47+#REF!+#REF!+#REF!+#REF!," ") -> #REF! | E47: =IF('001'!E47+Рабочие!E38+#REF!+#REF!+SDLG!E37+#REF!+#REF!+#REF!+#REF!+#REF!+#REF!+#REF!+#REF!+#REF!+#REF!+#REF!+#REF!+#REF!+'18'!E47+#REF!+#REF!+#REF!+#REF!,'001'!E47+Рабочие!E38+#REF!+#REF!+SDLG!E37+#REF!+#REF!+#REF!+#REF!+#REF!+#REF!+#REF!+#REF!+#REF!+#REF!+#REF!+#REF!+#REF!+'18'!E47+#REF!+#REF!+#REF!+#REF!," ") -> #REF! | F47: =IF('001'!F47+Рабочие!F38+#REF!+#REF!+SDLG!F37+#REF!+#REF!+#REF!+#REF!+#REF!+#REF!+#REF!+#REF!+#REF!+#REF!+#REF!+#REF!+#REF!+'18'!F47+#REF!+#REF!+#REF!+#REF!,'001'!F47+Рабочие!F38+#REF!+#REF!+SDLG!F37+#REF!+#REF!+#REF!+#REF!+#REF!+#REF!+#REF!+#REF!+#REF!+#REF!+#REF!+#REF!+#REF!+'18'!F47+#REF!+#REF!+#REF!+#REF!," ") -> #REF! | G47: =IF('001'!G47+Рабочие!G38+#REF!+#REF!+SDLG!G37+#REF!+#REF!+#REF!+#REF!+#REF!+#REF!+#REF!+#REF!+#REF!+#REF!+#REF!+#REF!+#REF!+'18'!G47+#REF!+#REF!+#REF!+#REF!,'001'!G47+Рабочие!G38+#REF!+#REF!+SDLG!G37+#REF!+#REF!+#REF!+#REF!+#REF!+#REF!+#REF!+#REF!+#REF!+#REF!+#REF!+#REF!+#REF!+'18'!G47+#REF!+#REF!+#REF!+#REF!," ") -> #REF! | H47: =IF('001'!H47+Рабочие!H38+#REF!+#REF!+SDLG!H37+#REF!+#REF!+#REF!+#REF!+#REF!+#REF!+#REF!+#REF!+#REF!+#REF!+#REF!+#REF!+#REF!+'18'!H47+#REF!+#REF!+#REF!+#REF!,'001'!H47+Рабочие!H38+#REF!+#REF!+SDLG!H37+#REF!+#REF!+#REF!+#REF!+#REF!+#REF!+#REF!+#REF!+#REF!+#REF!+#REF!+#REF!+#REF!+'18'!H47+#REF!+#REF!+#REF!+#REF!," ") -> #REF! | I47: =IF('001'!I47+Рабочие!I38+#REF!+#REF!+SDLG!I37+#REF!+#REF!+#REF!+#REF!+#REF!+#REF!+#REF!+#REF!+#REF!+#REF!+#REF!+#REF!+#REF!+'18'!I47+#REF!+#REF!+#REF!+#REF!,'001'!I47+Рабочие!I38+#REF!+#REF!+SDLG!I37+#REF!+#REF!+#REF!+#REF!+#REF!+#REF!+#REF!+#REF!+#REF!+#REF!+#REF!+#REF!+#REF!+'18'!I47+#REF!+#REF!+#REF!+#REF!," ") -> #REF! | J47: =IF('001'!J47+Рабочие!J38+#REF!+#REF!+SDLG!J37+#REF!+#REF!+#REF!+#REF!+#REF!+#REF!+#REF!+#REF!+#REF!+#REF!+#REF!+#REF!+#REF!+'18'!J47+#REF!+#REF!+#REF!+#REF!,'001'!J47+Рабочие!J38+#REF!+#REF!+SDLG!J37+#REF!+#REF!+#REF!+#REF!+#REF!+#REF!+#REF!+#REF!+#REF!+#REF!+#REF!+#REF!+#REF!+'18'!J47+#REF!+#REF!+#REF!+#REF!," ") -> #REF! | K47: =IF('001'!K47+Рабочие!K38+#REF!+#REF!+SDLG!K37+#REF!+#REF!+#REF!+#REF!+#REF!+#REF!+#REF!+#REF!+#REF!+#REF!+#REF!+#REF!+#REF!+'18'!K47+#REF!+#REF!+#REF!+#REF!,'001'!K47+Рабочие!K38+#REF!+#REF!+SDLG!K37+#REF!+#REF!+#REF!+#REF!+#REF!+#REF!+#REF!+#REF!+#REF!+#REF!+#REF!+#REF!+#REF!+'18'!K47+#REF!+#REF!+#REF!+#REF!," ") -> #REF! | ... S47: =IF('001'!S47+Рабочие!S38+#REF!+#REF!+SDLG!S37+#REF!+#REF!+#REF!+#REF!+#REF!+#REF!+#REF!+#REF!+#REF!+#REF!+#REF!+#REF!+#REF!+'18'!S47+#REF!+#REF!+#REF!+#REF!,'001'!S47+Рабочие!S38+#REF!+#REF!+SDLG!S37+#REF!+#REF!+#REF!+#REF!+#REF!+#REF!+#REF!+#REF!+#REF!+#REF!+#REF!+#REF!+#REF!+'18'!S47+#REF!+#REF!+#REF!+#REF!," ") -> #REF!
A48: 2 | B48: Лисай И. М. | C48: 6 | D48: =IF('001'!D48+Рабочие!D39+#REF!+#REF!+SDLG!#REF!+#REF!+#REF!+#REF!+#REF!+#REF!+#REF!+#REF!+#REF!+#REF!+#REF!+#REF!+#REF!+#REF!+'18'!D48+#REF!+#REF!+#REF!+#REF!,'001'!D48+Рабочие!D39+#REF!+#REF!+SDLG!#REF!+#REF!+#REF!+#REF!+#REF!+#REF!+#REF!+#REF!+#REF!+#REF!+#REF!+#REF!+#REF!+#REF!+'18'!D48+#REF!+#REF!+#REF!+#REF!," ") -> #REF! | E48: =IF('001'!E48+Рабочие!E39+#REF!+#REF!+SDLG!#REF!+#REF!+#REF!+#REF!+#REF!+#REF!+#REF!+#REF!+#REF!+#REF!+#REF!+#REF!+#REF!+#REF!+'18'!E48+#REF!+#REF!+#REF!+#REF!,'001'!E48+Рабочие!E39+#REF!+#REF!+SDLG!#REF!+#REF!+#REF!+#REF!+#REF!+#REF!+#REF!+#REF!+#REF!+#REF!+#REF!+#REF!+#REF!+#REF!+'18'!E48+#REF!+#REF!+#REF!+#REF!," ") -> #REF! | F48: =IF('001'!F48+Рабочие!F39+#REF!+#REF!+SDLG!#REF!+#REF!+#REF!+#REF!+#REF!+#REF!+#REF!+#REF!+#REF!+#REF!+#REF!+#REF!+#REF!+#REF!+'18'!F48+#REF!+#REF!+#REF!+#REF!,'001'!F48+Рабочие!F39+#REF!+#REF!+SDLG!#REF!+#REF!+#REF!+#REF!+#REF!+#REF!+#REF!+#REF!+#REF!+#REF!+#REF!+#REF!+#REF!+#REF!+'18'!F48+#REF!+#REF!+#REF!+#REF!," ") -> #REF! | G48: =IF('001'!G48+Рабочие!G39+#REF!+#REF!+SDLG!#REF!+#REF!+#REF!+#REF!+#REF!+#REF!+#REF!+#REF!+#REF!+#REF!+#REF!+#REF!+#REF!+#REF!+'18'!G48+#REF!+#REF!+#REF!+#REF!,'001'!G48+Рабочие!G39+#REF!+#REF!+SDLG!#REF!+#REF!+#REF!+#REF!+#REF!+#REF!+#REF!+#REF!+#REF!+#REF!+#REF!+#REF!+#REF!+#REF!+'18'!G48+#REF!+#REF!+#REF!+#REF!," ") -> #REF! | H48: =IF('001'!H48+Рабочие!H39+#REF!+#REF!+SDLG!#REF!+#REF!+#REF!+#REF!+#REF!+#REF!+#REF!+#REF!+#REF!+#REF!+#REF!+#REF!+#REF!+#REF!+'18'!H48+#REF!+#REF!+#REF!+#REF!,'001'!H48+Рабочие!H39+#REF!+#REF!+SDLG!#REF!+#REF!+#REF!+#REF!+#REF!+#REF!+#REF!+#REF!+#REF!+#REF!+#REF!+#REF!+#REF!+#REF!+'18'!H48+#REF!+#REF!+#REF!+#REF!," ") -> #REF! | I48: =IF('001'!I48+Рабочие!I39+#REF!+#REF!+SDLG!#REF!+#REF!+#REF!+#REF!+#REF!+#REF!+#REF!+#REF!+#REF!+#REF!+#REF!+#REF!+#REF!+#REF!+'18'!I48+#REF!+#REF!+#REF!+#REF!,'001'!I48+Рабочие!I39+#REF!+#REF!+SDLG!#REF!+#REF!+#REF!+#REF!+#REF!+#REF!+#REF!+#REF!+#REF!+#REF!+#REF!+#REF!+#REF!+#REF!+'18'!I48+#REF!+#REF!+#REF!+#REF!," ") -> #REF! | J48: =IF('001'!J48+Рабочие!J39+#REF!+#REF!+SDLG!#REF!+#REF!+#REF!+#REF!+#REF!+#REF!+#REF!+#REF!+#REF!+#REF!+#REF!+#REF!+#REF!+#REF!+'18'!J48+#REF!+#REF!+#REF!+#REF!,'001'!J48+Рабочие!J39+#REF!+#REF!+SDLG!#REF!+#REF!+#REF!+#REF!+#REF!+#REF!+#REF!+#REF!+#REF!+#REF!+#REF!+#REF!+#REF!+#REF!+'18'!J48+#REF!+#REF!+#REF!+#REF!," ") -> #REF! | K48: =IF('001'!K48+Рабочие!K39+#REF!+#REF!+SDLG!#REF!+#REF!+#REF!+#REF!+#REF!+#REF!+#REF!+#REF!+#REF!+#REF!+#REF!+#REF!+#REF!+#REF!+'18'!K48+#REF!+#REF!+#REF!+#REF!,'001'!K48+Рабочие!K39+#REF!+#REF!+SDLG!#REF!+#REF!+#REF!+#REF!+#REF!+#REF!+#REF!+#REF!+#REF!+#REF!+#REF!+#REF!+#REF!+#REF!+'18'!K48+#REF!+#REF!+#REF!+#REF!," ") -> #REF! | ... S48: =IF('001'!S48+Рабочие!S39+#REF!+#REF!+SDLG!#REF!+#REF!+#REF!+#REF!+#REF!+#REF!+#REF!+#REF!+#REF!+#REF!+#REF!+#REF!+#REF!+#REF!+'18'!S48+#REF!+#REF!+#REF!+#REF!,'001'!S48+Рабочие!S39+#REF!+#REF!+SDLG!#REF!+#REF!+#REF!+#REF!+#REF!+#REF!+#REF!+#REF!+#REF!+#REF!+#REF!+#REF!+#REF!+#REF!+'18'!S48+#REF!+#REF!+#REF!+#REF!," ") -> #REF! | T48: =SUM(D48:S49) -> #REF! | AG48: =AE95 -> #REF!
D49: =IF('001'!D49+Рабочие!D40+#REF!+#REF!+SDLG!#REF!+#REF!+#REF!+#REF!+#REF!+#REF!+#REF!+#REF!+#REF!+#REF!+#REF!+#REF!+#REF!+#REF!+'18'!D49+#REF!+#REF!+#REF!+#REF!,'001'!D49+Рабочие!D40+#REF!+#REF!+SDLG!#REF!+#REF!+#REF!+#REF!+#REF!+#REF!+#REF!+#REF!+#REF!+#REF!+#REF!+#REF!+#REF!+#REF!+'18'!D49+#REF!+#REF!+#REF!+#REF!," ") -> #REF! | E49: =IF('001'!E49+Рабочие!E40+#REF!+#REF!+SDLG!#REF!+#REF!+#REF!+#REF!+#REF!+#REF!+#REF!+#REF!+#REF!+#REF!+#REF!+#REF!+#REF!+#REF!+'18'!E49+#REF!+#REF!+#REF!+#REF!,'001'!E49+Рабочие!E40+#REF!+#REF!+SDLG!#REF!+#REF!+#REF!+#REF!+#REF!+#REF!+#REF!+#REF!+#REF!+#REF!+#REF!+#REF!+#REF!+#REF!+'18'!E49+#REF!+#REF!+#REF!+#REF!," ") -> #REF! | F49: =IF('001'!F49+Рабочие!F40+#REF!+#REF!+SDLG!#REF!+#REF!+#REF!+#REF!+#REF!+#REF!+#REF!+#REF!+#REF!+#REF!+#REF!+#REF!+#REF!+#REF!+'18'!F49+#REF!+#REF!+#REF!+#REF!,'001'!F49+Рабочие!F40+#REF!+#REF!+SDLG!#REF!+#REF!+#REF!+#REF!+#REF!+#REF!+#REF!+#REF!+#REF!+#REF!+#REF!+#REF!+#REF!+#REF!+'18'!F49+#REF!+#REF!+#REF!+#REF!," ") -> #REF! | G49: =IF('001'!G49+Рабочие!G40+#REF!+#REF!+SDLG!#REF!+#REF!+#REF!+#REF!+#REF!+#REF!+#REF!+#REF!+#REF!+#REF!+#REF!+#REF!+#REF!+#REF!+'18'!G49+#REF!+#REF!+#REF!+#REF!,'001'!G49+Рабочие!G40+#REF!+#REF!+SDLG!#REF!+#REF!+#REF!+#REF!+#REF!+#REF!+#REF!+#REF!+#REF!+#REF!+#REF!+#REF!+#REF!+#REF!+'18'!G49+#REF!+#REF!+#REF!+#REF!," ") -> #REF! | H49: =IF('001'!H49+Рабочие!H40+#REF!+#REF!+SDLG!#REF!+#REF!+#REF!+#REF!+#REF!+#REF!+#REF!+#REF!+#REF!+#REF!+#REF!+#REF!+#REF!+#REF!+'18'!H49+#REF!+#REF!+#REF!+#REF!,'001'!H49+Рабочие!H40+#REF!+#REF!+SDLG!#REF!+#REF!+#REF!+#REF!+#REF!+#REF!+#REF!+#REF!+#REF!+#REF!+#REF!+#REF!+#REF!+#REF!+'18'!H49+#REF!+#REF!+#REF!+#REF!," ") -> #REF! | I49: =IF('001'!I49+Рабочие!I40+#REF!+#REF!+SDLG!#REF!+#REF!+#REF!+#REF!+#REF!+#REF!+#REF!+#REF!+#REF!+#REF!+#REF!+#REF!+#REF!+#REF!+'18'!I49+#REF!+#REF!+#REF!+#REF!,'001'!I49+Рабочие!I40+#REF!+#REF!+SDLG!#REF!+#REF!+#REF!+#REF!+#REF!+#REF!+#REF!+#REF!+#REF!+#REF!+#REF!+#REF!+#REF!+#REF!+'18'!I49+#REF!+#REF!+#REF!+#REF!," ") -> #REF! | J49: =IF('001'!J49+Рабочие!J40+#REF!+#REF!+SDLG!#REF!+#REF!+#REF!+#REF!+#REF!+#REF!+#REF!+#REF!+#REF!+#REF!+#REF!+#REF!+#REF!+#REF!+'18'!J49+#REF!+#REF!+#REF!+#REF!,'001'!J49+Рабочие!J40+#REF!+#REF!+SDLG!#REF!+#REF!+#REF!+#REF!+#REF!+#REF!+#REF!+#REF!+#REF!+#REF!+#REF!+#REF!+#REF!+#REF!+'18'!J49+#REF!+#REF!+#REF!+#REF!," ") -> #REF! | K49: =IF('001'!K49+Рабочие!K40+#REF!+#REF!+SDLG!#REF!+#REF!+#REF!+#REF!+#REF!+#REF!+#REF!+#REF!+#REF!+#REF!+#REF!+#REF!+#REF!+#REF!+'18'!K49+#REF!+#REF!+#REF!+#REF!,'001'!K49+Рабочие!K40+#REF!+#REF!+SDLG!#REF!+#REF!+#REF!+#REF!+#REF!+#REF!+#REF!+#REF!+#REF!+#REF!+#REF!+#REF!+#REF!+#REF!+'18'!K49+#REF!+#REF!+#REF!+#REF!," ") -> #REF! | ... S49: =IF('001'!S49+Рабочие!S40+#REF!+#REF!+SDLG!#REF!+#REF!+#REF!+#REF!+#REF!+#REF!+#REF!+#REF!+#REF!+#REF!+#REF!+#REF!+#REF!+#REF!+'18'!S49+#REF!+#REF!+#REF!+#REF!,'001'!S49+Рабочие!S40+#REF!+#REF!+SDLG!#REF!+#REF!+#REF!+#REF!+#REF!+#REF!+#REF!+#REF!+#REF!+#REF!+#REF!+#REF!+#REF!+#REF!+'18'!S49+#REF!+#REF!+#REF!+#REF!," ") -> #REF!
A50: 3 | B50: Хилимончик Н. В. | C50: 6 | D50: =IF('001'!D50+Рабочие!D41+#REF!+#REF!+SDLG!#REF!+#REF!+#REF!+#REF!+#REF!+#REF!+#REF!+#REF!+#REF!+#REF!+#REF!+#REF!+#REF!+#REF!+'18'!D50+#REF!+#REF!+#REF!+#REF!,'001'!D50+Рабочие!D41+#REF!+#REF!+SDLG!#REF!+#REF!+#REF!+#REF!+#REF!+#REF!+#REF!+#REF!+#REF!+#REF!+#REF!+#REF!+#REF!+#REF!+'18'!D50+#REF!+#REF!+#REF!+#REF!," ") -> #REF! | E50: =IF('001'!E50+Рабочие!E41+#REF!+#REF!+SDLG!#REF!+#REF!+#REF!+#REF!+#REF!+#REF!+#REF!+#REF!+#REF!+#REF!+#REF!+#REF!+#REF!+#REF!+'18'!E50+#REF!+#REF!+#REF!+#REF!,'001'!E50+Рабочие!E41+#REF!+#REF!+SDLG!#REF!+#REF!+#REF!+#REF!+#REF!+#REF!+#REF!+#REF!+#REF!+#REF!+#REF!+#REF!+#REF!+#REF!+'18'!E50+#REF!+#REF!+#REF!+#REF!," ") -> #REF! | F50: =IF('001'!F50+Рабочие!F41+#REF!+#REF!+SDLG!#REF!+#REF!+#REF!+#REF!+#REF!+#REF!+#REF!+#REF!+#REF!+#REF!+#REF!+#REF!+#REF!+#REF!+'18'!F50+#REF!+#REF!+#REF!+#REF!,'001'!F50+Рабочие!F41+#REF!+#REF!+SDLG!#REF!+#REF!+#REF!+#REF!+#REF!+#REF!+#REF!+#REF!+#REF!+#REF!+#REF!+#REF!+#REF!+#REF!+'18'!F50+#REF!+#REF!+#REF!+#REF!," ") -> #REF! | G50: =IF('001'!G50+Рабочие!G41+#REF!+#REF!+SDLG!#REF!+#REF!+#REF!+#REF!+#REF!+#REF!+#REF!+#REF!+#REF!+#REF!+#REF!+#REF!+#REF!+#REF!+'18'!G50+#REF!+#REF!+#REF!+#REF!,'001'!G50+Рабочие!G41+#REF!+#REF!+SDLG!#REF!+#REF!+#REF!+#REF!+#REF!+#REF!+#REF!+#REF!+#REF!+#REF!+#REF!+#REF!+#REF!+#REF!+'18'!G50+#REF!+#REF!+#REF!+#REF!," ") -> #REF! | H50: =IF('001'!H50+Рабочие!H41+#REF!+#REF!+SDLG!#REF!+#REF!+#REF!+#REF!+#REF!+#REF!+#REF!+#REF!+#REF!+#REF!+#REF!+#REF!+#REF!+#REF!+'18'!H50+#REF!+#REF!+#REF!+#REF!,'001'!H50+Рабочие!H41+#REF!+#REF!+SDLG!#REF!+#REF!+#REF!+#REF!+#REF!+#REF!+#REF!+#REF!+#REF!+#REF!+#REF!+#REF!+#REF!+#REF!+'18'!H50+#REF!+#REF!+#REF!+#REF!," ") -> #REF! | I50: =IF('001'!I50+Рабочие!I41+#REF!+#REF!+SDLG!#REF!+#REF!+#REF!+#REF!+#REF!+#REF!+#REF!+#REF!+#REF!+#REF!+#REF!+#REF!+#REF!+#REF!+'18'!I50+#REF!+#REF!+#REF!+#REF!,'001'!I50+Рабочие!I41+#REF!+#REF!+SDLG!#REF!+#REF!+#REF!+#REF!+#REF!+#REF!+#REF!+#REF!+#REF!+#REF!+#REF!+#REF!+#REF!+#REF!+'18'!I50+#REF!+#REF!+#REF!+#REF!," ") -> #REF! | J50: =IF('001'!J50+Рабочие!J41+#REF!+#REF!+SDLG!#REF!+#REF!+#REF!+#REF!+#REF!+#REF!+#REF!+#REF!+#REF!+#REF!+#REF!+#REF!+#REF!+#REF!+'18'!J50+#REF!+#REF!+#REF!+#REF!,'001'!J50+Рабочие!J41+#REF!+#REF!+SDLG!#REF!+#REF!+#REF!+#REF!+#REF!+#REF!+#REF!+#REF!+#REF!+#REF!+#REF!+#REF!+#REF!+#REF!+'18'!J50+#REF!+#REF!+#REF!+#REF!," ") -> #REF! | K50: =IF('001'!K50+Рабочие!K41+#REF!+#REF!+SDLG!#REF!+#REF!+#REF!+#REF!+#REF!+#REF!+#REF!+#REF!+#REF!+#REF!+#REF!+#REF!+#REF!+#REF!+'18'!K50+#REF!+#REF!+#REF!+#REF!,'001'!K50+Рабочие!K41+#REF!+#REF!+SDLG!#REF!+#REF!+#REF!+#REF!+#REF!+#REF!+#REF!+#REF!+#REF!+#REF!+#REF!+#REF!+#REF!+#REF!+'18'!K50+#REF!+#REF!+#REF!+#REF!," ") -> #REF! | ... S50: =IF('001'!S50+Рабочие!S41+#REF!+#REF!+SDLG!#REF!+#REF!+#REF!+#REF!+#REF!+#REF!+#REF!+#REF!+#REF!+#REF!+#REF!+#REF!+#REF!+#REF!+'18'!S50+#REF!+#REF!+#REF!+#REF!,'001'!S50+Рабочие!S41+#REF!+#REF!+SDLG!#REF!+#REF!+#REF!+#REF!+#REF!+#REF!+#REF!+#REF!+#REF!+#REF!+#REF!+#REF!+#REF!+#REF!+'18'!S50+#REF!+#REF!+#REF!+#REF!," ") -> #REF! | T50: =SUM(D50:S51) -> #REF! | AG50: =AE96 -> #REF!
D51: =IF('001'!D51+Рабочие!D42+#REF!+#REF!+SDLG!#REF!+#REF!+#REF!+#REF!+#REF!+#REF!+#REF!+#REF!+#REF!+#REF!+#REF!+#REF!+#REF!+#REF!+'18'!D51+#REF!+#REF!+#REF!+#REF!,'001'!D51+Рабочие!D42+#REF!+#REF!+SDLG!#REF!+#REF!+#REF!+#REF!+#REF!+#REF!+#REF!+#REF!+#REF!+#REF!+#REF!+#REF!+#REF!+#REF!+'18'!D51+#REF!+#REF!+#REF!+#REF!," ") -> #REF! | E51: =IF('001'!E51+Рабочие!E42+#REF!+#REF!+SDLG!#REF!+#REF!+#REF!+#REF!+#REF!+#REF!+#REF!+#REF!+#REF!+#REF!+#REF!+#REF!+#REF!+#REF!+'18'!E51+#REF!+#REF!+#REF!+#REF!,'001'!E51+Рабочие!E42+#REF!+#REF!+SDLG!#REF!+#REF!+#REF!+#REF!+#REF!+#REF!+#REF!+#REF!+#REF!+#REF!+#REF!+#REF!+#REF!+#REF!+'18'!E51+#REF!+#REF!+#REF!+#REF!," ") -> #REF! | F51: =IF('001'!F51+Рабочие!F42+#REF!+#REF!+SDLG!#REF!+#REF!+#REF!+#REF!+#REF!+#REF!+#REF!+#REF!+#REF!+#REF!+#REF!+#REF!+#REF!+#REF!+'18'!F51+#REF!+#REF!+#REF!+#REF!,'001'!F51+Рабочие!F42+#REF!+#REF!+SDLG!#REF!+#REF!+#REF!+#REF!+#REF!+#REF!+#REF!+#REF!+#REF!+#REF!+#REF!+#REF!+#REF!+#REF!+'18'!F51+#REF!+#REF!+#REF!+#REF!," ") -> #REF! | G51: =IF('001'!G51+Рабочие!G42+#REF!+#REF!+SDLG!#REF!+#REF!+#REF!+#REF!+#REF!+#REF!+#REF!+#REF!+#REF!+#REF!+#REF!+#REF!+#REF!+#REF!+'18'!G51+#REF!+#REF!+#REF!+#REF!,'001'!G51+Рабочие!G42+#REF!+#REF!+SDLG!#REF!+#REF!+#REF!+#REF!+#REF!+#REF!+#REF!+#REF!+#REF!+#REF!+#REF!+#REF!+#REF!+#REF!+'18'!G51+#REF!+#REF!+#REF!+#REF!," ") -> #REF! | H51: =IF('001'!H51+Рабочие!H42+#REF!+#REF!+SDLG!#REF!+#REF!+#REF!+#REF!+#REF!+#REF!+#REF!+#REF!+#REF!+#REF!+#REF!+#REF!+#REF!+#REF!+'18'!H51+#REF!+#REF!+#REF!+#REF!,'001'!H51+Рабочие!H42+#REF!+#REF!+SDLG!#REF!+#REF!+#REF!+#REF!+#REF!+#REF!+#REF!+#REF!+#REF!+#REF!+#REF!+#REF!+#REF!+#REF!+'18'!H51+#REF!+#REF!+#REF!+#REF!," ") -> #REF! | I51: =IF('001'!I51+Рабочие!I42+#REF!+#REF!+SDLG!#REF!+#REF!+#REF!+#REF!+#REF!+#REF!+#REF!+#REF!+#REF!+#REF!+#REF!+#REF!+#REF!+#REF!+'18'!I51+#REF!+#REF!+#REF!+#REF!,'001'!I51+Рабочие!I42+#REF!+#REF!+SDLG!#REF!+#REF!+#REF!+#REF!+#REF!+#REF!+#REF!+#REF!+#REF!+#REF!+#REF!+#REF!+#REF!+#REF!+'18'!I51+#REF!+#REF!+#REF!+#REF!," ") -> #REF! | J51: =IF('001'!J51+Рабочие!J42+#REF!+#REF!+SDLG!#REF!+#REF!+#REF!+#REF!+#REF!+#REF!+#REF!+#REF!+#REF!+#REF!+#REF!+#REF!+#REF!+#REF!+'18'!J51+#REF!+#REF!+#REF!+#REF!,'001'!J51+Рабочие!J42+#REF!+#REF!+SDLG!#REF!+#REF!+#REF!+#REF!+#REF!+#REF!+#REF!+#REF!+#REF!+#REF!+#REF!+#REF!+#REF!+#REF!+'18'!J51+#REF!+#REF!+#REF!+#REF!," ") -> #REF! | K51: =IF('001'!K51+Рабочие!K42+#REF!+#REF!+SDLG!#REF!+#REF!+#REF!+#REF!+#REF!+#REF!+#REF!+#REF!+#REF!+#REF!+#REF!+#REF!+#REF!+#REF!+'18'!K51+#REF!+#REF!+#REF!+#REF!,'001'!K51+Рабочие!K42+#REF!+#REF!+SDLG!#REF!+#REF!+#REF!+#REF!+#REF!+#REF!+#REF!+#REF!+#REF!+#REF!+#REF!+#REF!+#REF!+#REF!+'18'!K51+#REF!+#REF!+#REF!+#REF!," ") -> #REF! | ... S51: =IF('001'!S51+Рабочие!S42+#REF!+#REF!+SDLG!#REF!+#REF!+#REF!+#REF!+#REF!+#REF!+#REF!+#REF!+#REF!+#REF!+#REF!+#REF!+#REF!+#REF!+'18'!S51+#REF!+#REF!+#REF!+#REF!,'001'!S51+Рабочие!S42+#REF!+#REF!+SDLG!#REF!+#REF!+#REF!+#REF!+#REF!+#REF!+#REF!+#REF!+#REF!+#REF!+#REF!+#REF!+#REF!+#REF!+'18'!S51+#REF!+#REF!+#REF!+#REF!," ") -> #REF!
A52: 4 | B52: Сильванович А. С. | C52: 5 | D52: =IF('001'!D52+Рабочие!#REF!+#REF!+#REF!+SDLG!#REF!+#REF!+#REF!+#REF!+#REF!+#REF!+#REF!+#REF!+#REF!+#REF!+#REF!+#REF!+#REF!+#REF!+'18'!D52+#REF!+#REF!+#REF!+#REF!,'001'!D52+Рабочие!#REF!+#REF!+#REF!+SDLG!#REF!+#REF!+#REF!+#REF!+#REF!+#REF!+#REF!+#REF!+#REF!+#REF!+#REF!+#REF!+#REF!+#REF!+'18'!D52+#REF!+#REF!+#REF!+#REF!," ") -> #REF! | E52: =IF('001'!E52+Рабочие!#REF!+#REF!+#REF!+SDLG!#REF!+#REF!+#REF!+#REF!+#REF!+#REF!+#REF!+#REF!+#REF!+#REF!+#REF!+#REF!+#REF!+#REF!+'18'!E52+#REF!+#REF!+#REF!+#REF!,'001'!E52+Рабочие!#REF!+#REF!+#REF!+SDLG!#REF!+#REF!+#REF!+#REF!+#REF!+#REF!+#REF!+#REF!+#REF!+#REF!+#REF!+#REF!+#REF!+#REF!+'18'!E52+#REF!+#REF!+#REF!+#REF!," ") -> #REF! | F52: =IF('001'!F52+Рабочие!#REF!+#REF!+#REF!+SDLG!#REF!+#REF!+#REF!+#REF!+#REF!+#REF!+#REF!+#REF!+#REF!+#REF!+#REF!+#REF!+#REF!+#REF!+'18'!F52+#REF!+#REF!+#REF!+#REF!,'001'!F52+Рабочие!#REF!+#REF!+#REF!+SDLG!#REF!+#REF!+#REF!+#REF!+#REF!+#REF!+#REF!+#REF!+#REF!+#REF!+#REF!+#REF!+#REF!+#REF!+'18'!F52+#REF!+#REF!+#REF!+#REF!," ") -> #REF! | G52: =IF('001'!G52+Рабочие!#REF!+#REF!+#REF!+SDLG!#REF!+#REF!+#REF!+#REF!+#REF!+#REF!+#REF!+#REF!+#REF!+#REF!+#REF!+#REF!+#REF!+#REF!+'18'!G52+#REF!+#REF!+#REF!+#REF!,'001'!G52+Рабочие!#REF!+#REF!+#REF!+SDLG!#REF!+#REF!+#REF!+#REF!+#REF!+#REF!+#REF!+#REF!+#REF!+#REF!+#REF!+#REF!+#REF!+#REF!+'18'!G52+#REF!+#REF!+#REF!+#REF!," ") -> #REF! | H52: =IF('001'!H52+Рабочие!#REF!+#REF!+#REF!+SDLG!#REF!+#REF!+#REF!+#REF!+#REF!+#REF!+#REF!+#REF!+#REF!+#REF!+#REF!+#REF!+#REF!+#REF!+'18'!H52+#REF!+#REF!+#REF!+#REF!,'001'!H52+Рабочие!#REF!+#REF!+#REF!+SDLG!#REF!+#REF!+#REF!+#REF!+#REF!+#REF!+#REF!+#REF!+#REF!+#REF!+#REF!+#REF!+#REF!+#REF!+'18'!H52+#REF!+#REF!+#REF!+#REF!," ") -> #REF! | I52: =IF('001'!I52+Рабочие!#REF!+#REF!+#REF!+SDLG!#REF!+#REF!+#REF!+#REF!+#REF!+#REF!+#REF!+#REF!+#REF!+#REF!+#REF!+#REF!+#REF!+#REF!+'18'!I52+#REF!+#REF!+#REF!+#REF!,'001'!I52+Рабочие!#REF!+#REF!+#REF!+SDLG!#REF!+#REF!+#REF!+#REF!+#REF!+#REF!+#REF!+#REF!+#REF!+#REF!+#REF!+#REF!+#REF!+#REF!+'18'!I52+#REF!+#REF!+#REF!+#REF!," ") -> #REF! | J52: =IF('001'!J52+Рабочие!#REF!+#REF!+#REF!+SDLG!#REF!+#REF!+#REF!+#REF!+#REF!+#REF!+#REF!+#REF!+#REF!+#REF!+#REF!+#REF!+#REF!+#REF!+'18'!J52+#REF!+#REF!+#REF!+#REF!,'001'!J52+Рабочие!#REF!+#REF!+#REF!+SDLG!#REF!+#REF!+#REF!+#REF!+#REF!+#REF!+#REF!+#REF!+#REF!+#REF!+#REF!+#REF!+#REF!+#REF!+'18'!J52+#REF!+#REF!+#REF!+#REF!," ") -> #REF! | K52: =IF('001'!K52+Рабочие!#REF!+#REF!+#REF!+SDLG!#REF!+#REF!+#REF!+#REF!+#REF!+#REF!+#REF!+#REF!+#REF!+#REF!+#REF!+#REF!+#REF!+#REF!+'18'!K52+#REF!+#REF!+#REF!+#REF!,'001'!K52+Рабочие!#REF!+#REF!+#REF!+SDLG!#REF!+#REF!+#REF!+#REF!+#REF!+#REF!+#REF!+#REF!+#REF!+#REF!+#REF!+#REF!+#REF!+#REF!+'18'!K52+#REF!+#REF!+#REF!+#REF!," ") -> #REF! | ... S52: =IF('001'!S52+Рабочие!#REF!+#REF!+#REF!+SDLG!#REF!+#REF!+#REF!+#REF!+#REF!+#REF!+#REF!+#REF!+#REF!+#REF!+#REF!+#REF!+#REF!+#REF!+'18'!S52+#REF!+#REF!+#REF!+#REF!,'001'!S52+Рабочие!#REF!+#REF!+#REF!+SDLG!#REF!+#REF!+#REF!+#REF!+#REF!+#REF!+#REF!+#REF!+#REF!+#REF!+#REF!+#REF!+#REF!+#REF!+'18'!S52+#REF!+#REF!+#REF!+#REF!," ") -> #REF! | T52: =SUM(D52:S53) -> #REF! | AG52: =AE97 -> #REF!
...

Sheet 001
B1: Миндорстрой РБ
A2: КУП Гроднооблдорстрой
A3: ДРСУ № 161 г. Щучин | G3: Наряд № _________________ | AA3: Сроки | AE3: план | AG3: факт
F4: на | I4: =ИТОГО!I4 -> Июль | Q4: =ИТОГО!Q4 -> 2025 | S4: г. | AA4: Начало работы
A5: Объект: | J5: по прямой сдельной системе оплаты труда | AA5: Окончание работы
A6: Прорабство: МУ-1 Асфальтоукладка
A7: Бригада: Асфальтоукладка | Q7: Шифр записи | V7: Номер документа | AA7: Шифр машины | AE7: Шифр работы
E9: Будущие периоды
A10: Шифр нормативного источника | B10: Описание работ и условий производства | G10: Ед. изм | I10: Задано | X10: Исполнено | AG10: шифр работы
I11: количество работ | M11: на единицу | T11: на весь объём | X11: количество работ | AA11: норма на выполненный объём, чел/час | AC11: норма времени, чел/час | AE11: сумма зарплаты
M12: норма времени чел/час | P12: расценка | T12: норма времени чел/час | V12: Сумма зарплаты
T14: =I14*M14 -> 0 | V14: =I14*P14 -> 0 | X14: =I14 -> 0 | AA14: =T14 -> 0 | AC14: =M14 -> 0 | AE14: =ROUND(V14,2) -> 0
T15: =I15*M15 -> 0 | V15: =I15*P15 -> 0 | X15: =I15 -> 0 | AA15: =T15 -> 0 | AC15: =M15 -> 0 | AE15: =ROUND(V15,2) -> 0
T16: =I16*M16 -> 0 | V16: =I16*P16 -> 0 | X16: =I16 -> 0 | AA16: =T16 -> 0 | AC16: =M16 -> 0 | AE16: =ROUND(V16,2) -> 0
T17: =I17*M17 -> 0 | V17: =I17*P17 -> 0 | X17: =I17 -> 0 | AA17: =T17 -> 0 | AC17: =M17 -> 0 | AE17: =ROUND(V17,2) -> 0
T18: =I18*M18 -> 0 | V18: =I18*P18 -> 0 | X18: =I18 -> 0 | AA18: =T18 -> 0 | AC18: =M18 -> 0 | AE18: =ROUND(V18,2) -> 0
T19: =I19*M19 -> 0 | V19: =I19*P19 -> 0 | X19: =I19 -> 0 | AA19: =T19 -> 0 | AC19: =M19 -> 0 | AE19: =ROUND(V19,2) -> 0
T20: =I20*M20 -> 0 | V20: =I20*P20 -> 0 | X20: =I20 -> 0 | AA20: =T20 -> 0 | AC20: =M20 -> 0 | AE20: =ROUND(V20,2) -> 0
T21: =I21*M21 -> 0 | V21: =I21*P21 -> 0 | X21: =I21 -> 0 | AA21: =T21 -> 0 | AC21: =M21 -> 0 | AE21: =ROUND(V21,2) -> 0
T22: =I22*M22 -> 0 | V22: =I22*P22 -> 0 | X22: =I22 -> 0 | AA22: =T22 -> 0 | AC22: =M22 -> 0 | AE22: =ROUND(V22,2) -> 0
T23: =I23*M23 -> 0 | V23: =I23*P23 -> 0 | X23: =I23 -> 0 | AA23: =T23 -> 0 | AC23: =M23 -> 0 | AE23: =ROUND(V23,2) -> 0
T24: =I24*M24 -> 0 | V24: =I24*P24 -> 0 | X24: =I24 -> 0 | AA24: =T24 -> 0 | AC24: =M24 -> 0 | AE24: =ROUND(V24,2) -> 0
T25: =I25*M25 -> 0 | V25: =I25*P25 -> 0 | X25: =I25 -> 0 | AA25: =T25 -> 0 | AC25: =M25 -> 0 | AE25: =ROUND(V25,2) -> 0
... T31: =I31*M31 -> 0 | V31: =I31*P31 -> 0 | X31: =I31 -> 0 | AA31: =T31 -> 0 | AC31: =M31 -> 0 | AE31: =ROUND(V31,2) -> 0
AB32: ИТОГО | AE32: =SUM(AE14:AF31) -> 0
B34: Задание выдал прораб (мастер) _______________ | G34: =I4 -> Июль | K34: =Q4 -> 2025 | M34: г. | T34: Задание принял бригадир ________________ | AC34: =I4 -> Июль | AD34: =Q4 -> 2025 | AE34: г.
D35: Работу принял с оценкой качества _______________________________________________
B36: Прораб (мастер) ___________________ | G36: =I4 -> Июль | K36: =Q4 -> 2025 | M36: г. | T36: Работу сдал бригадир ______________________ | AC36: =I4 -> Июль | AD36: =Q4 -> 2025 | AE36: г.
B38: =ИТОГО!B38 -> Нормы, расценки и сумма заработной платы проверил экономист: Яцевич Н. Г. ____________________ ________________________ " _____ " | AF38: =Q4 -> 2025 | AG38: г.
B40: Объёмы проверил: ________________Мархоцкая С. К.
D42: Табель расчёт | J42: =I4 -> Июль | P42: =Q4 -> 2025
A43: Табельный № | B43: Фамилия, И. О. | C43: Разряд | D43: Часы работы | T43: часов | Y43: дней | AB43: Причитается
D44: 1 | E44: 2 | F44: 3 | G44: 4 | H44: 5 | I44: 6 | J44: 7 | K44: 8 | L44: 9 | M44: 10 | N44: 11 | O44: 12 | P44: 13 | Q44: 14 | R44: 15 | S44: х | T44: отработано урочно | W44: в простое | X44: всего | Y44: сдельно | Z44: повремённо | AA44: всего | AB44: заработная плата | AF44: доплаты | AG44: всего к оплате
D45: 16 | E45: 17 | F45: 18 | G45: 19 | H45: 20 | I45: 21 | J45: 22 | K45: 23 | L45: 24 | M45: 25 | N45: 26 | O45: 27 | P45: 28 | Q45: 29 | R45: 30 | S45: 31 | T45: сдельно | U45: повремён | V45: сверурочно | AB45: сдельно | AC45: повременно | AD45: сверурочно | AE45: в простое
A46: 1 | B46: =ИТОГО!B46 -> Федюк В. В | C46: =ИТОГО!C46 -> 6 | T46: =SUM(D46:S47) -> 0 | X46: =SUM(T46:W47) -> 0 | Y46: =COUNT(D46:S47) -> 0 | AA46: =SUM(Y46:Z47) -> 0 | AG46: =AE94 -> 0
A48: 2 | B48: =ИТОГО!B48 -> Лисай И. М. | C48: =ИТОГО!C48 -> 6 | T48: =SUM(D48:S49) -> 0 | X48: =SUM(T48:W49) -> 0 | Y48: =COUNT(D48:S49) -> 0 | AA48: =SUM(Y48:Z49) -> 0 | AG48: =AE95 -> 0
A50: 3 | B50: =ИТОГО!B50 -> Хилимончик Н. В. | C50: =ИТОГО!C50 -> 6 | T50: =SUM(D50:S51) -> 0 | X50: =SUM(T50:W51) -> 0 | Y50: =COUNT(D50:S51) -> 0 | AA50: =SUM(Y50:Z51) -> 0 | AG50: =AE96 -> 0
A52: 4 | B52: =ИТОГО!B52 -> Сильванович А. С. | C52: =ИТОГО!C52 -> 5 | T52: =SUM(D52:S53) -> 0 | X52: =SUM(T52:W53) -> 0 | Y52: =COUNT(D52:S53) -> 0 | AA52: =SUM(Y52:Z53) -> 0 | AG52: =AE97 -> 0
A54: 5 | B54: =ИТОГО!B54 -> Масюкевич Ю В. | C54: =ИТОГО!C54 -> 5 | T54: =SUM(D54:S55) -> 0 | X54: =SUM(T54:W55) -> 0 | Y54: =COUNT(D54:S55) -> 0 | AA54: =SUM(Y54:Z55) -> 0 | AG54: =AE98 -> 0
A56: 6 | B56: =ИТОГО!B56 -> Сидорович А. П. | C56: =ИТОГО!C56 -> 4 | T56: =SUM(D56:S57) -> 0 | X56: =SUM(T56:W57) -> 0 | Y56: =COUNT(D56:S57) -> 0 | AA56: =SUM(Y56:Z57) -> 0 | AG56: =AE99 -> 0
...

Sheet Рабочие
B1: Миндорстрой РБ
A2: КУП Гроднооблдорстрой
A3: ДРСУ № 161 г. Щучин | G3: Наряд № _________________ | AA3: Сроки | AE3: план | AG3: факт
F4: на | I4: Июль | Q4: 2024 | S4: г. | AA4: Начало работы | AE4: 01 | AG4: 01
A5: Объект:Бол.Можейкова - Ищелно | J5: по прямой сдельной системе оплаты труда | AA5: Окончание работы | AE5: 30 | AG5: 30
A6: Прорабство: ПУ-3
A7: Бригада: ПУ-3 | Q7: Шифр записи | V7: Номер документа | AA7: Шифр машины | AE7: Шифр работы
A10: Шифр нормативного источника | B10: Описание работ и условий производства | G10: Ед. изм | I10: Задано | X10: Исполнено | AG10: шифр работы
I11: количество работ | M11: на единицу | T11: на весь объём | X11: количество работ | AA11: норма на выполненный объём, чел/час | AC11: норма времени, чел/час | AE11: сумма зарплаты
M12: норма времени чел/час | P12: расценка | T12: норма времени чел/час | V12: Сумма зарплаты
A14: ТЕ01-40-1 | B14: Обрезка крон деревьев высоторезом | G14: 100 крон | I14: 0.11 | M14: 6.57 | P14: 14.65 | T14: =I14*M14 -> 0.7227 | V14: =I14*P14 -> 1.6115 | X14: =I14 -> 0.11 | AA14: =T14 -> 0.7227 | AC14: =M14 -> 6.57 | AE14: =ROUND(V14,2) -> 1.61
A15: Е70-48-10 Нзтр = 1.15 Нэкспл = 1,15 | B15: Установка дорожных знаков в грунтах | G15: 10 ст. | I15: 1.6 | M15: 19.65 | P15: 36.14 | T15: =I15*M15 -> 31.44 | V15: =I15*P15 -> 57.824 | X15: =I15 -> 1.6 | AA15: =T15 -> 31.44 | AC15: =M15 -> 19.65 | AE15: =V15 -> 57.824
A16: ТЕ 04 -5-3 КСУ = 1,15 | B16: Окраска стоек дорожных знаков | G16: 100 шт | I16: 0.16 | M16: 30.9 | P16: 59.33 | T16: =I16*M16 -> 4.944 | V16: =P16*I16 -> 9.4928 | X16: =I16 -> 0.16 | AA16: =T16 -> 4.944 | AC16: =M16 -> 30.9 | AE16: =V16 -> 9.4928
A17: Е70-50-1 Нвсего = 0,8 Нзтр = 1,15 Нэкспл = 1,15 | B17: Демонтпж щитков дор. Знаков | G17: 1 шт | I17: 15 | M17: 0.24 | P17: 0.42 | T17: =I17*M17 -> 3.6 | V17: =I17*P17 -> 6.3 | X17: =I17 -> 15 | AA17: =T17 -> 3.6 | AC17: =M17 -> 0.24 | AE17: =V17 -> 6.3
A18: Е51-7-1 | B18: Погрузка в ручную сподручных и навальных грузов | G18: тн | I18: 0.399 | M18: 0.6 | P18: 1.15 | T18: =I18*M18 -> 0.2394 | V18: =I18*P18 -> 0.45885 | X18: =I18 -> 0.399 | AA18: =T18 -> 0.2394 | AC18: =M18 -> 0.6 | AE18: =V18 -> 0.45885
A19: Е51-7-4 | B19: Выгрузка в ручную сподручных и навальных грузов | G19: тн | I19: 0.399 | M19: 0.48 | P19: 0.92 | T19: =I19*M19 -> 0.19152 | V19: =I19*P19 -> 0.36708 | X19: =I19 -> 0.399 | AA19: =T19 -> 0.19152 | AC19: =M19 -> 0.48 | AE19: =V19 -> 0.36708
A20: Е70-230-1 Нвсего=0,8 Нзтр = 1,15 Нэкспл = 1,15 | B20: Демонтаж одностороних дорожных знаков на одной стойке | G20: 1 знак | I20: 10 | M20: 0.87 | P20: 1.55 | T20: =I20*M20 -> 8.7 | V20: =I20*P20 -> 15.5 | X20: =I20 -> 10 | AA20: =T20 -> 8.7 | AC20: =M20 -> 0.87 | AE20: =ROUND(V20,2) -> 15.5
B21: Отработана по часовой | G21: ч\ч | T21: =I21*M21 -> 0 | AA21: =T21 -> 0 | AC21: =M21 -> 0
T22: =I22*M22 -> 0 | V22: =I22*P22 -> 0 | X22: =I22 -> 0 | AA22: =T22 -> 0 | AC22: =M22 -> 0 | AE22: =ROUND(V22,2) -> 0
T23: =SUM(T14:U22) -> 49.83762 | AB23: ИТОГО | AE23: =AE14+AE15+AE16+AE17+AE18+AE19+AE20 -> 91.55273
B25: Задание выдал прораб (мастер) _______________ | G25: =I4 -> Июль | K25: =Q4 -> 2024 | M25: г. | T25: Задание принял бригадир ________________ | AC25: =I4 -> Июль | AD25: =Q4 -> 2024 | AE25: г.
D26: Работу принял с оценкой качества _______________________________________________
B27: Прораб (мастер) ___________________ | G27: =I4 -> Июль | K27: =Q4 -> 2024 | M27: г. | T27: Работу сдал бригадир ______________________ | AC27: =I4 -> Июль | AD27: =Q4 -> 2024 | AE27: г.
B29: =ИТОГО!B38 -> Нормы, расценки и сумма заработной платы проверил экономист: Яцевич Н. Г. ____________________ ________________________ " _____ " | AF29: =Q4 -> 2024 | AG29: г.
B31: Объёмы проверил: ________________
D33: Табель расчёт | J33: =I4 -> Июль | P33: =Q4 -> 2024
A34: Табельный № | B34: Фамилия, И. О. | C34: Разряд | D34: Часы работы | T34: часов | Y34: дней | AB34: Причитается
D35: 1 | E35: 2 | F35: 3 | G35: 4 | H35: 5 | I35: 6 | J35: 7 | K35: 8 | L35: 9 | M35: 10 | N35: 11 | O35: 12 | P35: 13 | Q35: 14 | R35: 15 | S35: х | T35: отработано урочно | W35: в простое | X35: всего | Y35: сдельно | Z35: повремённо | AA35: всего | AB35: заработная плата | AF35: доплаты | AG35: всего к оплате
D36: 16 | E36: 17 | F36: 18 | G36: 19 | H36: 20 | I36: 21 | J36: 22 | K36: 23 | L36: 24 | M36: 25 | N36: 26 | O36: 27 | P36: 28 | Q36: 29 | R36: 30 | S36: 31 | T36: сдельно | U36: повремён | V36: сверурочно | AB36: сдельно | AC36: повременно | AD36: сверурочно | AE36: в простое
A37: 1 | B37: Хитинов А.А. | C37: 4 | N37: 8 | U37: 8 | X37: =SUM(T37:W38) -> 8 | Z37: 1 | AA37: =SUM(Y37:Z38) -> 1 | AG37: 16.96
N38: 8
A39: 2 | B39: Васюк И.И. | C39: 3 | L39: 8 | U39: 16 | X39: =SUM(T39:W40) -> 16 | Z39: 2 | AA39: =SUM(Y39:Z40) -> 2 | AG39: 29.12
A41: 3 | B41: Богдан П.Г. | C41: 4 | K41: 8 | L41: 8 | M41: 8 | N41: 8 | U41: 16 | X41: =SUM(T41:W42) -> 16 | Z41: 2 | AA41: =SUM(Y41:Z42) -> 2 | AG41: 29.12
A43: 4 | B43: Кособуцкий О.Я. | C43: 3 | U43: 16 | X43: =SUM(T43:W44) -> 16 | Z43: 2 | AA43: =SUM(Y43:Z44) -> 2 | AG43: 29.12
O44: 8
A45: 5 | B45: Лисай И.М, | C45: 3 | E45: 7 | U45: 8 | X45: =SUM(T45:W46) -> 8 | Z45: 1 | AA45: =SUM(Y45:Z46) -> 1 | AG45: 14.56
A47: 6 | U47: 16 | X47: =SUM(T47:W48) -> 16 | Z47: 2 | AA47: =SUM(Y47:Z48) -> 2 | AG47: 33.92
U49: 8 | X49: =SUM(T49:W50) -> 8 | Z49: 1 | AA49: =SUM(Y49:Z50) -> 1 | AG49: 14.56
U51: 8 | X51: =SUM(T51:W52) -> 8 | Z51: 1 | AA51: =SUM(Y51:Z52) -> 1 | AG51: 16.96
U53: 8 | X53: =SUM(T53:W54) -> 8 | Z53: 1 | AA53: =SUM(Y53:Z54) -> 1 | AG53: 14.56
...

Sheet SDLG
B1: Миндорстрой РБ
A2: КУП Гроднооблдорстрой
A3: ДРСУ № 161 г. Щучин | G3: Наряд № _________________ | AA3: Сроки | AE3: план | AG3: факт
F4: на | I4: =ИТОГО!I4 -> Июль | Q4: =ИТОГО!Q4 -> 2025 | S4: г. | AA4: Начало работы | AE4: 01 | AG4: 01
A5: Объект: Содержание | J5: по прямой сдельной системе оплаты труда | AA5: Окончание работы
A6: Прорабство: МУ-1 Асфальтоукладка | E6: Автогрейдер
A7: Бригада: | B7: Стубеда В. Т. | Q7: Шифр записи | V7: Номер документа | AA7: Шифр машины | AE7: Шифр работы
C8: SDLG
E9: Будущие периоды
A10: Шифр нормативного источника | B10: Описание работ и условий производства | G10: Ед. изм | I10: Задано | X10: Исполнено | AG10: шифр работы
I11: количество работ | M11: на единицу | T11: на весь объём | X11: количество работ | AA11: норма на выполненный объём, чел/час | AC11: норма времени, чел/час | AE11: сумма зарплаты
M12: норма времени чел/час | P12: расценка | T12: норма времени чел/час | V12: Сумма зарплаты
A14: Е70-220-1 | B14: РЕМОНТНОЕ ПРОФИЛИРОВАНИЕ ГРАВИЙНЫХ ДОРОГ АВТОГРЕЙДЕРОМ СРЕДНЕГО ТИПА, ШИРИНА ПРОФИЛИРУЕМОЙ ДОРОГИ ДО 7 М | G14: 1 км. спрофилированной дороги | I14: =#REF! -> #REF! | M14: 1.08 | P14: 2.03 | T14: =I14*M14 -> #REF! | V14: =I14*P14 -> #REF! | X14: =I14 -> #REF! | AA14: =T14 -> #REF! | AC14: =M14 -> 1.08 | AE14: =ROUND(V14,2) -> #REF!
A15: Е70-220-2 | B15: РЕМОНТНОЕ ПРОФИЛИРОВАНИЕ ГРАВИЙНЫХ ДОРОГ АВТОГРЕЙДЕРОМ СРЕДНЕГО ТИПА, ШИРИНА ПРОФИЛИРУЕМОЙ ДОРОГИ ДО 9 М | G15: 1 км. спрофилированной дороги | I15: =#REF! -> #REF! | M15: 1.25 | P15: 2.35 | T15: =I15*M15 -> #REF! | V15: =I15*P15 -> #REF! | X15: =I15 -> #REF! | AA15: =T15 -> #REF! | AC15: =M15 -> 1.25 | AE15: =ROUND(V15,2) -> #REF!
A16: Е70-220-3 | B16: РЕМОНТНОЕ ПРОФИЛИРОВАНИЕ ГРАВИЙНЫХ ДОРОГ АВТОГРЕЙДЕРОМ СРЕДНЕГО ТИПА, ШИРИНА ПРОФИЛИРУЕМОЙ ДОРОГИ ДО 11 М | G16: 1 км. спрофилированной дороги | I16: =#REF! -> #REF! | M16: 1.48 | P16: 2.78 | T16: =I16*M16 -> #REF! | V16: =I16*P16 -> #REF! | X16: =I16 -> #REF! | AA16: =T16 -> #REF! | AC16: =M16 -> 1.48 | AE16: =ROUND(V16,2) -> #REF!
A17: Е70-220-4 | B17: РЕМОНТНОЕ ПРОФИЛИРОВАНИЕ ГРУНТОВЫХ И УЛУЧШЕННЫХ ГРУНТОВЫХ ДОРОГ АВТОГРЕЙДЕРОМ СРЕДНЕГО ТИПА, ШИРИНА ПРОФИЛИРУЕМОЙ ДОРОГИ ДО 7 М | G17: 1 км. спрофилированной дороги | I17: =#REF! -> #REF! | M17: 1.01 | P17: 1.9 | T17: =I17*M17 -> #REF! | V17: =I17*P17 -> #REF! | X17: =I17 -> #REF! | AA17: =T17 -> #REF! | AC17: =M17 -> 1.01 | AE17: =ROUND(V17,2) -> #REF!
A18: ЕУ07-2-2 | B18: ПРОБЕГ К МЕСТУ РАБОТЫ ИЛИ ПЕРЕЕЗД С ОДНОГО ОБЪЕКТА НА ДРУГОЙ ИЛИ К МЕСТУ БАЗИРОВАНИЯ АВТОГРЕЙДЕРА СРЕДНЕГО ТИПА ПРИ ДВИЖЕНИИ ПО АВТОМОБИЛЬНЫМ ДОРОГАМ I И II КАТЕГОРИЙ | G18: 1 км пробега | I18: =#REF! -> #REF! | M18: 0.037 | P18: 0.07 | T18: =I18*M18 -> #REF! | V18: =I18*P18 -> #REF! | X18: =I18 -> #REF! | AA18: =T18 -> #REF! | AC18: =M18 -> 0.037 | AE18: =ROUND(V18,2) -> #REF!
T19: =I19*M19 -> 0 | V19: =I19*P19 -> 0 | X19: =I19 -> 0 | AA19: =T19 -> 0 | AC19: =M19 -> 0 | AE19: =ROUND(V19,2) -> 0
T20: =I20*M20 -> 0 | V20: =I20*P20 -> 0 | X20: =I20 -> 0 | AA20: =T20 -> 0 | AC20: =M20 -> 0 | AE20: =ROUND(V20,2) -> 0
T21: =I21*M21 -> 0 | V21: =I21*P21 -> 0 | X21: =I21 -> 0 | AA21: =T21 -> 0 | AC21: =M21 -> 0 | AE21: =ROUND(V21,2) -> 0
AB22: ИТОГО | AE22: =SUM(AE14:AF21) -> #REF!
B24: Задание выдал прораб (мастер) _______________ | G24: =I4 -> Июль | K24: =Q4 -> 2025 | M24: г. | T24: Задание принял бригадир ________________ | AC24: =I4 -> Июль | AD24: =Q4 -> 2025 | AE24: г.
D25: Работу принял с оценкой качества _______________________________________________
B26: Прораб (мастер) ___________________ | G26: =I4 -> Июль | K26: =Q4 -> 2025 | M26: г. | T26: Работу сдал бригадир ______________________ | AC26: =I4 -> Июль | AD26: =Q4 -> 2025 | AE26: г.
B28: =ИТОГО!B38 -> Нормы, расценки и сумма заработной платы проверил экономист: Яцевич Н. Г. ____________________ ________________________ " _____ " | AF28: =Q4 -> 2025 | AG28: г.
B30: Объёмы проверил: ________________Мархоцкая С. К.
D32: Табель расчёт | J32: =I4 -> Июль | P32: =Q4 -> 2025
A33: Табельный № | B33: Фамилия, И. О. | C33: Разряд | D33: Часы работы | T33: часов | Y33: дней | AB33: Причитается
D34: 1 | E34: 2 | F34: 3 | G34: 4 | H34: 5 | I34: 6 | J34: 7 | K34: 8 | L34: 9 | M34: 10 | N34: 11 | O34: 12 | P34: 13 | Q34: 14 | R34: 15 | S34: х | T34: отработано урочно | W34: в простое | X34: всего | Y34: сдельно | Z34: повремённо | AA34: всего | AB34: заработная плата | AF34: доплаты | AG34: всего к оплате
D35: 16 | E35: 17 | F35: 18 | G35: 19 | H35: 20 | I35: 21 | J35: 22 | K35: 23 | L35: 24 | M35: 25 | N35: 26 | O35: 27 | P35: 28 | Q35: 29 | R35: 30 | S35: 31 | T35: сдельно | U35: повремён | V35: сверурочно | AB35: сдельно | AC35: повременно | AD35: сверурочно | AE35: в простое
A36: 1 | B36: =B7 -> Стубеда В. Т. | C36: =ИТОГО!C46 -> 6 | D36: 8 | G36: 8 | T36: =SUM(D36:S37) -> 16 | X36: =SUM(T36:W37) -> 16 | Y36: =COUNT(D36:S37) -> 2 | AA36: =SUM(Y36:Z37) -> 2 | AG36: =AE60 -> #REF!
A38: 14 | B38: =ИТОГО!B72 -> 0 | C38: =ИТОГО!C72 -> 0 | T38: =SUM(D38:S39) -> 0 | X38: =SUM(T38:W39) -> 0 | Y38: =COUNT(D38:S39) -> 0 | AA38: =SUM(Y38:Z39) -> 0 | AG38: =AE61 -> #REF!
Q40: Итого | T40: =SUM(T36:T39) -> 16 | X40: =SUM(X36:X39) -> 16 | Y40: =SUM(Y36:Y39) -> 2 | AA40: =SUM(AA36:AA39) -> 2 | AG40: =SUM(AG36:AG39) -> #REF!
B42: Примечание:1. Часы простоя подтверждают сигнальными извещениями ф.з-д | T42: Табель вёл: (бригадир, прораб, ст.мастер) _________________________ О. Л. Титяк
B43: Сверхурочная работа подтверждается разрешением профсоюзного комитета в каждом отдельном случае | T43: Сумма заработной платы:
B44: Разряды, тарифные ставки, расчёты распределения заработной платы проверил:
B45: =ИТОГО!B79 -> Экономист Яцевич Н. Г. ______________________________ | T45: премия, руб. _____________________________________
T46: К выплате утверждаются: | Z46: =ИТОГО!Z80 -> Нач ДРСУ 161 _______________ Залога Г.Ч.
C47: "___ " __________________ | L47: =Q4 -> 2025 | N47: г. | Z47: =ИТОГО!Z81 -> мастер __________________Голец П.В.
X48: " ___ " _______________________ | AE48: =Q4 -> 2025 | AF48: г.
...

Sheet 18
B1: Миндорстрой РБ
A2: КУП Гроднооблдорстрой
A3: ДРСУ № 161 г. Щучин | G3: Наряд № _________________ | AA3: Сроки | AE3: план | AG3: факт
F4: на | Q4: 2026 | S4: г. | AA4: Начало работы
A5: Объект: Содержание | J5: по прямой сдельной системе оплаты труда | AA5: Окончание работы
A6: Прорабство:
A7: Бригада: | Q7: Шифр записи | V7: Номер документа | AA7: Шифр машины | AE7: Шифр работы
A10: Шифр нормативного источника | B10: Описание работ и условий производства | G10: Ед. изм | I10: Задано | X10: Исполнено | AG10: шифр работы
I11: количество работ | M11: на единицу | T11: на весь объём | X11: количество работ | AA11: норма на выполненный объём, чел/час | AC11: норма времени, чел/час | AE11: сумма зарплаты
M12: норма времени чел/час | P12: расценка | T12: норма времени чел/час | V12: Сумма зарплаты
AB32: ИТОГО | AE32: =SUM(AE14:AF31) -> 0
B34: Задание выдал прораб (мастер) _______________ | G34: =I4 -> 0 | K34: =Q4 -> 2026 | M34: г. | T34: Задание принял бригадир ________________ | AC34: =I4 -> 0 | AD34: =Q4 -> 2026 | AE34: г.
D35: Работу принял с оценкой качества _______________________________________________
B36: Прораб (мастер) ___________________ | G36: =I4 -> 0 | K36: =Q4 -> 2026 | M36: г. | T36: Работу сдал бригадир ______________________ | AC36: =I4 -> 0 | AD36: =Q4 -> 2026 | AE36: г.
B38: =ИТОГО!B38 -> Нормы, расценки и сумма заработной платы проверил экономист: Яцевич Н. Г. ____________________ ________________________ " _____ " | AF38: =Q4 -> 2026 | AG38: г.
B40: Объёмы проверил: ________________
D42: Табель расчёт | J42: =I4 -> 0 | P42: =Q4 -> 2026
A43: Табельный № | B43: Фамилия, И. О. | C43: Разряд | D43: Часы работы | T43: часов | Y43: дней | AB43: Причитается
D44: 1 | E44: 2 | F44: 3 | G44: 4 | H44: 5 | I44: 6 | J44: 7 | K44: 8 | L44: 9 | M44: 10 | N44: 11 | O44: 12 | P44: 13 | Q44: 14 | R44: 15 | S44: х | T44: отработано урочно | W44: в простое | X44: всего | Y44: сдельно | Z44: повремённо | AA44: всего | AB44: заработная плата | AF44: доплаты | AG44: всего к оплате
D45: 16 | E45: 17 | F45: 18 | G45: 19 | H45: 20 | I45: 21 | J45: 22 | K45: 23 | L45: 24 | M45: 25 | N45: 26 | O45: 27 | P45: 28 | Q45: 29 | R45: 30 | S45: 31 | T45: сдельно | U45: повремён | V45: сверурочно | AB45: сдельно | AC45: повременно | AD45: сверурочно | AE45: в простое
A46: 1 | T46: =SUM(D46:S47) -> 0 | X46: =SUM(T46:W47) -> 0 | Y46: =COUNT(D46:S47) -> 0 | AA46: =SUM(Y46:Z47) -> 0 | AG46: =AE94 -> 0
A48: 2 | T48: =SUM(D48:S49) -> 0 | X48: =SUM(T48:W49) -> 0 | Y48: =COUNT(D48:S49) -> 0 | AA48: =SUM(Y48:Z49) -> 0 | AG48: =AE95 -> 0
A50: 3 | T50: =SUM(D50:S51) -> 0 | X50: =SUM(T50:W51) -> 0 | Y50: =COUNT(D50:S51) -> 0 | AA50: =SUM(Y50:Z51) -> 0 | AG50: =AE96 -> 0
A52: 4 | T52: =SUM(D52:S53) -> 0 | X52: =SUM(T52:W53) -> 0 | Y52: =COUNT(D52:S53) -> 0 | AA52: =SUM(Y52:Z53) -> 0 | AG52: =AE97 -> 0
A54: 5 | T54: =SUM(D54:S55) -> 0 | X54: =SUM(T54:W55) -> 0 | Y54: =COUNT(D54:S55) -> 0 | AA54: =SUM(Y54:Z55) -> 0 | AG54: =AE98 -> 0
A56: 6 | T56: =SUM(D56:S57) -> 0 | X56: =SUM(T56:W57) -> 0 | Y56: =COUNT(D56:S57) -> 0 | AA56: =SUM(Y56:Z57) -> 0 | AG56: =AE99 -> 0
A58: 7 | T58: =SUM(D58:S59) -> 0 | X58: =SUM(T58:W59) -> 0 | Y58: =COUNT(D58:S59) -> 0 | AA58: =SUM(Y58:Z59) -> 0 | AG58: =AE100 -> 0
A60: 8 | T60: =SUM(D60:S61) -> 0 | X60: =SUM(T60:W61) -> 0 | Y60: =COUNT(D60:S61) -> 0 | AA60: =SUM(Y60:Z61) -> 0 | AG60: =AE101 -> 0
A62: 9 | T62: =SUM(D62:S63) -> 0 | X62: =SUM(T62:W63) -> 0 | Y62: =COUNT(D62:S63) -> 0 | AA62: =SUM(Y62:Z63) -> 0 | AG62: =AE102 -> 0
A64: 10 | T64: =SUM(D64:S65) -> 0 | X64: =SUM(T64:W65) -> 0 | Y64: =COUNT(D64:S65) -> 0 | AA64: =SUM(Y64:Z65) -> 0 | AG64: =AE103 -> 0
A66: 11 | T66: =SUM(D66:S67) -> 0 | X66: =SUM(T66:W67) -> 0 | Y66: =COUNT(D66:S67) -> 0 | AA66: =SUM(Y66:Z67) -> 0 | AG66: =AE104 -> 0
A68: 12 | T68: =SUM(D68:S69) -> 0 | X68: =SUM(T68:W69) -> 0 | Y68: =COUNT(D68:S69) -> 0 | AA68: =SUM(Y68:Z69) -> 0 | AG68: =AE105 -> 0
A70: 13 | T70: =SUM(D70:S71) -> 0 | X70: =SUM(T70:W71) -> 0 | Y70: =COUNT(D70:S71) -> 0 | AA70: =SUM(Y70:Z71) -> 0 | AG70: =AE106 -> 0
A72: 14 | T72: =SUM(D72:S73) -> 0 | X72: =SUM(T72:W73) -> 0 | Y72: =COUNT(D72:S73) -> 0 | AA72: =SUM(Y72:Z73) -> 0 | AG72: =AE107 -> 0
Q74: Итого | T74: =SUM(T46:T73) -> 0 | X74: =SUM(X46:X73) -> 0 | Y74: =SUM(Y46:Y73) -> 0 | AA74: =SUM(AA46:AA73) -> 0 | AG74: =SUM(AG46:AG73) -> 0
B76: Примечание:1. Часы простоя подтверждают сигнальными извещениями ф.з-д | T76: Табель вёл: (бригадир, прораб, ст.мастер) _________________________ О. Л. Титяк
B77: Сверхурочная работа подтверждается разрешением профсоюзного комитета в каждом отдельном случае | T77: Сумма заработной платы:
B78: Разряды, тарифные ставки, расчёты распределения заработной платы проверил:
B79: =ИТОГО!B79 -> Экономист Яцевич Н. Г. ______________________________ | T79: премия, руб. _____________________________________
T80: К выплате утверждаются: | Z80: =ИТОГО!Z80 -> Нач ДРСУ 161 _______________ Залога Г.Ч.
...
